<?xml version="1.0" encoding="UTF-8"?>
<TestLog><TestSuite name="Master Test Suite"><TestCase name="async_out_future" file="async_fut.cpp" line="32"><Info file="async_fut.cpp" line="58"><![CDATA[check !ec has passed]]></Info><Info file="async_fut.cpp" line="63"><![CDATA[check fut.valid() has passed]]></Info><Info file="async_fut.cpp" line="64"><![CDATA[check fut_in.valid() has passed]]></Info><Info file="async_fut.cpp" line="65"><![CDATA[check 'no exceptions thrown by fut_in.get()' has passed]]></Info><Info file="async_fut.cpp" line="69"><![CDATA[check 'no exceptions thrown by line = fut.get()' has passed]]></Info><Info file="async_fut.cpp" line="72"><![CDATA[check line.size() >= val.size() has passed]]></Info><Info file="async_fut.cpp" line="74"><![CDATA[check boost::algorithm::starts_with(line, val) has passed]]></Info><TestingTime>34000</TestingTime></TestCase></TestSuite></TestLog>